Workbook

Sheet Raw RetailSalesData
A1: OrderID | B1: OrderDate | C1: CustomerID | D1: ProductID | E1: UnitsSold | F1: PricePerUnit | G1: TotalRevenue | H1: Region | I1: Country | J1: City | K1: SalesPerson | L1: CustomerType
A2: ORD-10001 | B2: 2024-01-30 | C2: CUST-1143 | D2: C302 | E2: 18 | F2: 45 | G2: 810.00 | H2: LATAM | I2: Brazil | K2: Sales Rep 4 | L2: Returning
A3: ORD-10002 | B3: 2023-01-03 | C3: CUST-1061 | D3: C301 | E3: 3 | F3: 60 | G3: 180.00 | H3: NA | I3: USA | J3: Chicago | K3: Sales Rep 5 | L3: VIP
A4: ORD-10003 | B4: 2024-03-19 | C4: CUST-1021 | D4: C303 | E4: 15 | F4: 60 | G4: 900.00 | H4: EMEA | I4: Germany | J4: Berlin | K4: Sales Rep 5 | L4: VIP
A5: ORD-10004 | B5: 2023-08-29 | C5: CUST-1079 | D5: P103 | E5: 3 | F5: 95 | G5: 285.00 | H5: EMEA | I5: Germany | J5: Berlin | K5: Sales Rep 3 | L5: New
A6: ORD-10005 | B6: 2025-08-31 | C6: CUST-1041 | D6: P202 | E6: 7 | F6: 70 | G6: 490.00 | H6: NA | I6: USA | J6: New York | K6: Michael Johnson | L6: Returning
A7: ORD-10006 | B7: 2022-07-06 | C7: CUST-1125 | D7: C302 | E7: 14 | F7: 50 | G7: 700.00 | H7: EMEA | I7: Germany | J7: Berlin | K7: Sales Rep 1 | L7: New
A8: ORD-10007 | B8: 2024-09-28 | C8: CUST-1161 | D8: P103 | E8: 6 | F8: 90 | G8: 540.00 | H8: LATAM | I8: Brazil | J8: SÃ£o Paulo | K8: Sales Rep 2 | L8: VIP
A9: UNKNOWN | B9: 2024-09-09 | C9: CUST-1153 | D9: P103 | E9: 19 | F9: 95 | G9: 1805.00 | H9: APAC | I9: Japan | J9: Tokyo | K9: Hiroshi Tanaka | L9: VIP
A10: ORD-10009 | B10: 2022-07-29 | C10: CUST-1012 | D10: C301 | E10: 2 | F10: 60 | G10: 120.00 | H10: NA | I10: USA | J10: New York | K10: Michael Johnson | L10: VIP
A11: ORD-10010 | B11: 2026-03-13 | C11: CUST-1130 | D11: P103 | E11: 3 | F11: 95 | G11: 285.00 | H11: EMEA | I11: UK | J11: London | K11: John Smith | L11: Returning
A12: ORD-10011 | B12: 2022-05-28 | C12: CUST-1127 | D12: C302 | F12: 45 | G12: 270.00 | H12: LATAM | I12: Argentina | J12: Buenos Aires | K12: Sales Rep 2 | L12: New
A13: ORD-10012 | B13: 2022-03-26 | C13: CUST-1161 | D13: P203 | E13: 7 | F13: 63 | G13: 441.00 | H13: LATAM | I13: Brazil | J13: SÃ£o Paulo | K13: Unknown | L13: Returning
A14: ORD-10013 | B14: 2025-11-30 | C14: CUST-1027 | D14: C303 | E14: 8 | F14: 65 | G14: 520.00 | H14: NA | I14: Canada | J14: Toronto | K14: Sales Rep 3 | L14: VIP
A15: ORD-10014 | B15: 2024-09-30 | C15: CUST-1058 | D15: P202 | E15: 2 | F15: 60 | G15: 120.00 | H15: LATAM | I15: Argentina | J15: Buenos Aires | K15: Sales Rep 4 | L15: Returning
A16: ORD-10015 | B16: 2023-09-15 | C16: CUST-1139 | D16: C302 | E16: 17 | F16: 50 | G16: 850.00 | H16: EMEA | I16: Germany | J16: Berlin | K16: Sales Rep 4
A17: ORD-10016 | B17: 2024-07-08 | D17: P203 | E17: 19 | F17: 63 | G17: 1197.00 | H17: LATAM | I17: Brazil | J17: SÃ£o Paulo | K17: Sales Rep 5 | L17: Returning
A18: ORD-10017 | B18: 2024-09-30 | C18: CUST-1166 | D18: C303 | E18: 9 | F18: 55 | G18: 495.00 | H18: LATAM | I18: Brazil | J18: SÃ£o Paulo | K18: Sales Rep 5 | L18: Returning
A19: ORD-10018 | B19: 2026-05-30 | C19: CUST-1143 | D19: C301 | E19: 18 | F19: 60 | G19: 1080.00 | H19: NA | I19: USA | J19: Chicago | K19: Sales Rep 1 | L19: New
A20: ORD-10019 | B20: 2023-06-17 | C20: CUST-1193 | D20: P203 | E20: 14 | F20: 73 | G20: 1022.00 | H20: NA | I20: USA | J20: Chicago | K20: Sales Rep 2 | L20: New
A21: ORD-10020 | B21: 2023-08-28 | C21: CUST-1158 | D21: C304 | E21: 18 | F21: 63 | G21: 1134.00 | H21: NA | I21: Canada | J21: Toronto | K21: Sales Rep 5 | L21: VIP
A22: ORD-10021 | B22: 2022-03-28 | C22: CUST-1051 | D22: C301 | E22: 7 | F22: 60 | G22: 420.00 | H22: NA | I22: USA | J22: New York | K22: Michael Johnson | L22: VIP
A23: ORD-10022 | B23: 2022-10-01 | C23: CUST-1175 | D23: P203 | E23: 11 | F23: 68 | H23: APAC | I23: Japan | J23: Tokyo | K23: Hiroshi Tanaka | L23: Returning
A24: ORD-10023 | B24: 2025-06-18 | C24: CUST-1077 | D24: C302 | E24: 10 | F24: 45 | G24: 450.00 | H24: LATAM | I24: Argentina | J24: Buenos Aires | K24: Sales Rep 1 | L24: VIP
A25: UNKNOWN | B25: 2023-03-28 | C25: CUST-1042 | D25: P202 | E25: 8 | F25: 60 | G25: 480.00 | H25: LATAM | I25: Brazil | J25: SÃ£o Paulo | K25: Sales Rep 3 | L25: New
A26: ORD-10025 | B26: 2022-11-03 | C26: CUST-1100 | D26: P101 | E26: 3 | F26: 85 | G26: 255.00 | H26: EMEA | I26: Germany | J26: Berlin | K26: Sales Rep 2 | L26: New
A27: ORD-10027 | B27: 2024-02-24 | C27: CUST-1057 | D27: C302 | E27: 3 | F27: 50 | G27: 150.00 | H27: APAC | I27: India | J27: Mumbai | K27: Aarav Patel | L27: New
A28: ORD-10028 | B28: 2023-10-03 | C28: CUST-1078 | D28: P202 | E28: 15 | F28: 65 | G28: 975.00 | H28: EMEA | I28: UK | J28: London | K28: John Smith | L28: New
A29: ORD-10029 | C29: CUST-1054 | D29: C301 | E29: 12 | F29: 55 | G29: 660.00 | H29: EMEA | I29: Germany | J29: Berlin | K29: Sales Rep 2 | L29: Returning
A30: ORD-10030 | B30: 2025-10-18 | C30: CUST-1119 | D30: C304 | E30: 8 | F30: 58 | G30: 464.00 | H30: APAC | I30: Japan | J30: Tokyo | K30: Hiroshi Tanaka | L30: Returning
A31: ORD-10031 | B31: 2023-04-21 | C31: CUST-1015 | D31: P102 | E31: 19 | F31: 75 | G31: 1425.00 | H31: LATAM | I31: Brazil | J31: SÃ£o Paulo | K31: Unknown | L31: VIP
A32: ORD-10032 | B32: 2024-01-07 | C32: CUST-1063 | D32: P102 | E32: 11 | F32: 75 | G32: 825.00 | H32: LATAM | I32: Argentina | J32: Buenos Aires | K32: Sales Rep 4 | L32: VIP
A33: ORD-10033 | B33: 2023-07-22 | C33: CUST-1003 | D33: P101 | E33: 14 | F33: 80 | G33: 1120.00 | H33: LATAM | I33: Brazil | J33: SÃ£o Paulo | K33: Sales Rep 4 | L33: Returning
A34: ORD-10034 | B34: 2024-08-22 | C34: CUST-1114 | D34: C303 | E34: 20 | F34: 60 | G34: 1200.00 | H34: APAC | I34: Australia | J34: Sydney | K34: Sales Rep 3 | L34: VIP
A35: ORD-10035 | B35: 2025-10-07 | C35: CUST-1120 | D35: C302 | E35: 18 | G35: 900.00 | H35: APAC | I35: India | J35: Bangalore | K35: Sales Rep 5 | L35: Returning
A36: ORD-10037 | B36: #N/A | C36: CUST-1076 | D36: P103 | E36: 19 | F36: 90 | G36: 1710.00 | H36: LATAM | I36: Argentina | J36: Buenos Aires | K36: Sales Rep 4 | L36: Returning
A37: ORD-10038 | B37: 2024-01-29 | C37: CUST-1076 | D37: P103 | E37: 19 | F37: 90 | G37: 1710.00 | H37: LATAM | I37: Argentina | J37: Buenos Aires | K37: Sales Rep 4 | L37: Returning
A38: ORD-10039 | B38: 2024-07-15 | C38: CUST-1079 | D38: C301 | E38: 19 | F38: 55 | G38: 1045.00 | H38: APAC | I38: Japan | J38: Tokyo | K38: Hiroshi Tanaka | L38: VIP
A39: ORD-10041 | B39: 2023-03-11 | C39: CUST-1076 | E39: 3 | F39: 65 | G39: 195.00 | H39: APAC | I39: India | J39: Bangalore | K39: Sales Rep 2 | L39: Returning
A40: ORD-10042 | B40: 2023-05-23 | C40: CUST-1080 | D40: P202 | E40: 17 | F40: 65 | G40: 1105.00 | H40: EMEA | I40: Germany | J40: Berlin | K40: Sales Rep 2 | L40: Returning
...

Sheet Imputed Retail sales data 
A1: Order Id | B1: Date | C1: Customer id | D1: Product id | E1: Unite sold | F1: Price per unit | G1: Total Revenue | H1: Region | I1: Country | J1: City | K1: SalesPerson | L1: CustomerType
A2: =IF(COUNTIF('Raw RetailSalesData'!$A:$L,'Raw RetailSalesData'!A2)=1,'Raw RetailSalesData'!A2,"") -> ORD-10001 | B2: =IF('Raw RetailSalesData'!B2="","UNKNOWN",'Raw RetailSalesData'!B2) -> 2024-01-30 | C2: =IF('Raw RetailSalesData'!C2="","UNKNOW",'Raw RetailSalesData'!C2) -> CUST-1143 | D2: =IF('Raw RetailSalesData'!D2="","UNKNOW",'Raw RetailSalesData'!D2) -> C302 | E2: =IF('Raw RetailSalesData'!E2="",'Raw RetailSalesData'!F2/'Raw RetailSalesData'!G2,'Raw RetailSalesData'!E2) -> 18 | F2: =IF('Raw RetailSalesData'!F2="",'Raw RetailSalesData'!G2/'Raw RetailSalesData'!E2,'Raw RetailSalesData'!F2) -> 45 | G2: =F2*E2 -> 810 | H2: =IF('Raw RetailSalesData'!H2="","Unknown",'Raw RetailSalesData'!H2) -> LATAM | I2: Brazil | J2: Unknown | K2: =TRIM('Raw RetailSalesData'!K2) -> Sales Rep 4 | L2: Returning
A3: =IF(COUNTIF('Raw RetailSalesData'!$A:$L,'Raw RetailSalesData'!A3)=1,'Raw RetailSalesData'!A3,"") -> ORD-10002 | B3: =IF('Raw RetailSalesData'!B3="","UNKNOWN",'Raw RetailSalesData'!B3) -> 2023-01-03 | C3: =IF('Raw RetailSalesData'!C3="","UNKNOW",'Raw RetailSalesData'!C3) -> CUST-1061 | D3: =IF('Raw RetailSalesData'!D3="","UNKNOW",'Raw RetailSalesData'!D3) -> C301 | E3: =IF('Raw RetailSalesData'!E3="",'Raw RetailSalesData'!F3/'Raw RetailSalesData'!G3,'Raw RetailSalesData'!E3) -> 3 | F3: =IF('Raw RetailSalesData'!F3="",'Raw RetailSalesData'!G3/'Raw RetailSalesData'!E3,'Raw RetailSalesData'!F3) -> 60 | G3: =F3*E3 -> 180 | H3: =IF('Raw RetailSalesData'!H3="","Unknown",'Raw RetailSalesData'!H3) -> NA | I3: USA | J3: Chicago | K3: =TRIM('Raw RetailSalesData'!K3) -> Sales Rep 5 | L3: VIP
A4: =IF(COUNTIF('Raw RetailSalesData'!$A:$L,'Raw RetailSalesData'!A4)=1,'Raw RetailSalesData'!A4,"") -> ORD-10003 | B4: =IF('Raw RetailSalesData'!B4="","UNKNOWN",'Raw RetailSalesData'!B4) -> 2024-03-19 | C4: =IF('Raw RetailSalesData'!C4="","UNKNOW",'Raw RetailSalesData'!C4) -> CUST-1021 | D4: =IF('Raw RetailSalesData'!D4="","UNKNOW",'Raw RetailSalesData'!D4) -> C303 | E4: =IF('Raw RetailSalesData'!E4="",'Raw RetailSalesData'!F4/'Raw RetailSalesData'!G4,'Raw RetailSalesData'!E4) -> 15 | F4: =IF('Raw RetailSalesData'!F4="",'Raw RetailSalesData'!G4/'Raw RetailSalesData'!E4,'Raw RetailSalesData'!F4) -> 60 | G4: =F4*E4 -> 900 | H4: =IF('Raw RetailSalesData'!H4="","Unknown",'Raw RetailSalesData'!H4) -> EMEA | I4: Germany | J4: Berlin | K4: =TRIM('Raw RetailSalesData'!K4) -> Sales Rep 5 | L4: VIP
A5: =IF(COUNTIF('Raw RetailSalesData'!$A:$L,'Raw RetailSalesData'!A5)=1,'Raw RetailSalesData'!A5,"") -> ORD-10004 | B5: =IF('Raw RetailSalesData'!B5="","UNKNOWN",'Raw RetailSalesData'!B5) -> 2023-08-29 | C5: =IF('Raw RetailSalesData'!C5="","UNKNOW",'Raw RetailSalesData'!C5) -> CUST-1079 | D5: =IF('Raw RetailSalesData'!D5="","UNKNOW",'Raw RetailSalesData'!D5) -> P103 | E5: =IF('Raw RetailSalesData'!E5="",'Raw RetailSalesData'!F5/'Raw RetailSalesData'!G5,'Raw RetailSalesData'!E5) -> 3 | F5: =IF('Raw RetailSalesData'!F5="",'Raw RetailSalesData'!G5/'Raw RetailSalesData'!E5,'Raw RetailSalesData'!F5) -> 95 | G5: =F5*E5 -> 285 | H5: =IF('Raw RetailSalesData'!H5="","Unknown",'Raw RetailSalesData'!H5) -> EMEA | I5: Germany | J5: Berlin | K5: =TRIM('Raw RetailSalesData'!K5) -> Sales Rep 3 | L5: New
A6: =IF(COUNTIF('Raw RetailSalesData'!$A:$L,'Raw RetailSalesData'!A6)=1,'Raw RetailSalesData'!A6,"") -> ORD-10005 | B6: =IF('Raw RetailSalesData'!B6="","UNKNOWN",'Raw RetailSalesData'!B6) -> 2025-08-31 | C6: =IF('Raw RetailSalesData'!C6="","UNKNOW",'Raw RetailSalesData'!C6) -> CUST-1041 | D6: =IF('Raw RetailSalesData'!D6="","UNKNOW",'Raw RetailSalesData'!D6) -> P202 | E6: =IF('Raw RetailSalesData'!E6="",'Raw RetailSalesData'!F6/'Raw RetailSalesData'!G6,'Raw RetailSalesData'!E6) -> 7 | F6: =IF('Raw RetailSalesData'!F6="",'Raw RetailSalesData'!G6/'Raw RetailSalesData'!E6,'Raw RetailSalesData'!F6) -> 70 | G6: =F6*E6 -> 490 | H6: =IF('Raw RetailSalesData'!H6="","Unknown",'Raw RetailSalesData'!H6) -> NA | I6: USA | J6: NewYork | K6: =TRIM('Raw RetailSalesData'!K6) -> Michael Johnson | L6: Returning
A7: =IF(COUNTIF('Raw RetailSalesData'!$A:$L,'Raw RetailSalesData'!A7)=1,'Raw RetailSalesData'!A7,"") -> ORD-10006 | B7: =IF('Raw RetailSalesData'!B7="","UNKNOWN",'Raw RetailSalesData'!B7) -> 2022-07-06 | C7: =IF('Raw RetailSalesData'!C7="","UNKNOW",'Raw RetailSalesData'!C7) -> CUST-1125 | D7: =IF('Raw RetailSalesData'!D7="","UNKNOW",'Raw RetailSalesData'!D7) -> C302 | E7: =IF('Raw RetailSalesData'!E7="",'Raw RetailSalesData'!F7/'Raw RetailSalesData'!G7,'Raw RetailSalesData'!E7) -> 14 | F7: =IF('Raw RetailSalesData'!F7="",'Raw RetailSalesData'!G7/'Raw RetailSalesData'!E7,'Raw RetailSalesData'!F7) -> 50 | G7: =F7*E7 -> 700 | H7: =IF('Raw RetailSalesData'!H7="","Unknown",'Raw RetailSalesData'!H7) -> EMEA | I7: Germany | J7: Berlin | K7: =TRIM('Raw RetailSalesData'!K7) -> Sales Rep 1 | L7: New
A8: =IF(COUNTIF('Raw RetailSalesData'!$A:$L,'Raw RetailSalesData'!A8)=1,'Raw RetailSalesData'!A8,"") -> ORD-10007 | B8: =IF('Raw RetailSalesData'!B8="","UNKNOWN",'Raw RetailSalesData'!B8) -> 2024-09-28 | C8: =IF('Raw RetailSalesData'!C8="","UNKNOW",'Raw RetailSalesData'!C8) -> CUST-1161 | D8: =IF('Raw RetailSalesData'!D8="","UNKNOW",'Raw RetailSalesData'!D8) -> P103 | E8: =IF('Raw RetailSalesData'!E8="",'Raw RetailSalesData'!F8/'Raw RetailSalesData'!G8,'Raw RetailSalesData'!E8) -> 6 | F8: =IF('Raw RetailSalesData'!F8="",'Raw RetailSalesData'!G8/'Raw RetailSalesData'!E8,'Raw RetailSalesData'!F8) -> 90 | G8: =F8*E8 -> 540 | H8: =IF('Raw RetailSalesData'!H8="","Unknown",'Raw RetailSalesData'!H8) -> LATAM | I8: Brazil | J8: SÃ£oPaulo | K8: =TRIM('Raw RetailSalesData'!K8) -> Sales Rep 2 | L8: VIP
A9: UNKNOWN | B9: =IF('Raw RetailSalesData'!B9="","UNKNOWN",'Raw RetailSalesData'!B9) -> 2024-09-09 | C9: =IF('Raw RetailSalesData'!C9="","UNKNOW",'Raw RetailSalesData'!C9) -> CUST-1153 | D9: =IF('Raw RetailSalesData'!D9="","UNKNOW",'Raw RetailSalesData'!D9) -> P103 | E9: =IF('Raw RetailSalesData'!E9="",'Raw RetailSalesData'!F9/'Raw RetailSalesData'!G9,'Raw RetailSalesData'!E9) -> 19 | F9: =IF('Raw RetailSalesData'!F9="",'Raw RetailSalesData'!G9/'Raw RetailSalesData'!E9,'Raw RetailSalesData'!F9) -> 95 | G9: =F9*E9 -> 1805 | H9: =IF('Raw RetailSalesData'!H9="","Unknown",'Raw RetailSalesData'!H9) -> APAC | I9: Japan | J9: Tokyo | K9: =TRIM('Raw RetailSalesData'!K9) -> Hiroshi Tanaka | L9: VIP
A10: =IF(COUNTIF('Raw RetailSalesData'!$A:$L,'Raw RetailSalesData'!A10)=1,'Raw RetailSalesData'!A10,"") -> ORD-10009 | B10: =IF('Raw RetailSalesData'!B10="","UNKNOWN",'Raw RetailSalesData'!B10) -> 2022-07-29 | C10: =IF('Raw RetailSalesData'!C10="","UNKNOW",'Raw RetailSalesData'!C10) -> CUST-1012 | D10: =IF('Raw RetailSalesData'!D10="","UNKNOW",'Raw RetailSalesData'!D10) -> C301 | E10: =IF('Raw RetailSalesData'!E10="",'Raw RetailSalesData'!F10/'Raw RetailSalesData'!G10,'Raw RetailSalesData'!E10) -> 2 | F10: =IF('Raw RetailSalesData'!F10="",'Raw RetailSalesData'!G10/'Raw RetailSalesData'!E10,'Raw RetailSalesData'!F10) -> 60 | G10: =F10*E10 -> 120 | H10: =IF('Raw RetailSalesData'!H10="","Unknown",'Raw RetailSalesData'!H10) -> NA | I10: USA | J10: NewYork | K10: =TRIM('Raw RetailSalesData'!K10) -> Michael Johnson | L10: VIP
A11: =IF(COUNTIF('Raw RetailSalesData'!$A:$L,'Raw RetailSalesData'!A11)=1,'Raw RetailSalesData'!A11,"") -> ORD-10010 | B11: =IF('Raw RetailSalesData'!B11="","UNKNOWN",'Raw RetailSalesData'!B11) -> 2026-03-13 | C11: =IF('Raw RetailSalesData'!C11="","UNKNOW",'Raw RetailSalesData'!C11) -> CUST-1130 | D11: =IF('Raw RetailSalesData'!D11="","UNKNOW",'Raw RetailSalesData'!D11) -> P103 | E11: =IF('Raw RetailSalesData'!E11="",'Raw RetailSalesData'!F11/'Raw RetailSalesData'!G11,'Raw RetailSalesData'!E11) -> 3 | F11: =IF('Raw RetailSalesData'!F11="",'Raw RetailSalesData'!G11/'Raw RetailSalesData'!E11,'Raw RetailSalesData'!F11) -> 95 | G11: =F11*E11 -> 285 | H11: =IF('Raw RetailSalesData'!H11="","Unknown",'Raw RetailSalesData'!H11) -> EMEA | I11: UK | J11: London | K11: =TRIM('Raw RetailSalesData'!K11) -> John Smith | L11: Returning
A12: =IF(COUNTIF('Raw RetailSalesData'!$A:$L,'Raw RetailSalesData'!A12)=1,'Raw RetailSalesData'!A12,"") -> ORD-10011 | B12: =IF('Raw RetailSalesData'!B12="","UNKNOWN",'Raw RetailSalesData'!B12) -> 2022-05-28 | C12: =IF('Raw RetailSalesData'!C12="","UNKNOW",'Raw RetailSalesData'!C12) -> CUST-1127 | D12: =IF('Raw RetailSalesData'!D12="","UNKNOW",'Raw RetailSalesData'!D12) -> C302 | E12: =IF('Raw RetailSalesData'!E12="",'Raw RetailSalesData'!F12/'Raw RetailSalesData'!G12,'Raw RetailSalesData'!E12) -> 0.16666667 | F12: =IF('Raw RetailSalesData'!F12="",'Raw RetailSalesData'!G12/'Raw RetailSalesData'!E12,'Raw RetailSalesData'!F12) -> 45 | G12: =F12*E12 -> 7.5 | H12: =IF('Raw RetailSalesData'!H12="","Unknown",'Raw RetailSalesData'!H12) -> LATAM | I12: Argentina | J12: BuenosAires | K12: =TRIM('Raw RetailSalesData'!K12) -> Sales Rep 2 | L12: New
A13: =IF(COUNTIF('Raw RetailSalesData'!$A:$L,'Raw RetailSalesData'!A13)=1,'Raw RetailSalesData'!A13,"") -> ORD-10012 | B13: =IF('Raw RetailSalesData'!B13="","UNKNOWN",'Raw RetailSalesData'!B13) -> 2022-03-26 | C13: =IF('Raw RetailSalesData'!C13="","UNKNOW",'Raw RetailSalesData'!C13) -> CUST-1161 | D13: =IF('Raw RetailSalesData'!D13="","UNKNOW",'Raw RetailSalesData'!D13) -> P203 | E13: =IF('Raw RetailSalesData'!E13="",'Raw RetailSalesData'!F13/'Raw RetailSalesData'!G13,'Raw RetailSalesData'!E13) -> 7 | F13: =IF('Raw RetailSalesData'!F13="",'Raw RetailSalesData'!G13/'Raw RetailSalesData'!E13,'Raw RetailSalesData'!F13) -> 63 | G13: =F13*E13 -> 441 | H13: =IF('Raw RetailSalesData'!H13="","Unknown",'Raw RetailSalesData'!H13) -> LATAM | I13: Brazil | J13: SÃ£oPaulo | K13: =TRIM('Raw RetailSalesData'!K13) -> Unknown | L13: Returning
A14: =IF(COUNTIF('Raw RetailSalesData'!$A:$L,'Raw RetailSalesData'!A14)=1,'Raw RetailSalesData'!A14,"") -> ORD-10013 | B14: =IF('Raw RetailSalesData'!B14="","UNKNOWN",'Raw RetailSalesData'!B14) -> 2025-11-30 | C14: =IF('Raw RetailSalesData'!C14="","UNKNOW",'Raw RetailSalesData'!C14) -> CUST-1027 | D14: =IF('Raw RetailSalesData'!D14="","UNKNOW",'Raw RetailSalesData'!D14) -> C303 | E14: =IF('Raw RetailSalesData'!E14="",'Raw RetailSalesData'!F14/'Raw RetailSalesData'!G14,'Raw RetailSalesData'!E14) -> 8 | F14: =IF('Raw RetailSalesData'!F14="",'Raw RetailSalesData'!G14/'Raw RetailSalesData'!E14,'Raw RetailSalesData'!F14) -> 65 | G14: =F14*E14 -> 520 | H14: =IF('Raw RetailSalesData'!H14="","Unknown",'Raw RetailSalesData'!H14) -> NA | I14: Canada | J14: Toronto | K14: =TRIM('Raw RetailSalesData'!K14) -> Sales Rep 3 | L14: VIP
A15: =IF(COUNTIF('Raw RetailSalesData'!$A:$L,'Raw RetailSalesData'!A15)=1,'Raw RetailSalesData'!A15,"") -> ORD-10014 | B15: =IF('Raw RetailSalesData'!B15="","UNKNOWN",'Raw RetailSalesData'!B15) -> 2024-09-30 | C15: =IF('Raw RetailSalesData'!C15="","UNKNOW",'Raw RetailSalesData'!C15) -> CUST-1058 | D15: =IF('Raw RetailSalesData'!D15="","UNKNOW",'Raw RetailSalesData'!D15) -> P202 | E15: =IF('Raw RetailSalesData'!E15="",'Raw RetailSalesData'!F15/'Raw RetailSalesData'!G15,'Raw RetailSalesData'!E15) -> 2 | F15: =IF('Raw RetailSalesData'!F15="",'Raw RetailSalesData'!G15/'Raw RetailSalesData'!E15,'Raw RetailSalesData'!F15) -> 60 | G15: =F15*E15 -> 120 | H15: =IF('Raw RetailSalesData'!H15="","Unknown",'Raw RetailSalesData'!H15) -> LATAM | I15: Argentina | J15: BuenosAires | K15: =TRIM('Raw RetailSalesData'!K15) -> Sales Rep 4 | L15: Returning
A16: =IF(COUNTIF('Raw RetailSalesData'!$A:$L,'Raw RetailSalesData'!A16)=1,'Raw RetailSalesData'!A16,"") -> ORD-10015 | B16: =IF('Raw RetailSalesData'!B16="","UNKNOWN",'Raw RetailSalesData'!B16) -> 2023-09-15 | C16: =IF('Raw RetailSalesData'!C16="","UNKNOW",'Raw RetailSalesData'!C16) -> CUST-1139 | D16: =IF('Raw RetailSalesData'!D16="","UNKNOW",'Raw RetailSalesData'!D16) -> C302 | E16: =IF('Raw RetailSalesData'!E16="",'Raw RetailSalesData'!F16/'Raw RetailSalesData'!G16,'Raw RetailSalesData'!E16) -> 17 | F16: =IF('Raw RetailSalesData'!F16="",'Raw RetailSalesData'!G16/'Raw RetailSalesData'!E16,'Raw RetailSalesData'!F16) -> 50 | G16: =F16*E16 -> 850 | H16: =IF('Raw RetailSalesData'!H16="","Unknown",'Raw RetailSalesData'!H16) -> EMEA | I16: Germany | J16: Berlin | K16: =TRIM('Raw RetailSalesData'!K16) -> Sales Rep 4 | L16: Unknown
A17: =IF(COUNTIF('Raw RetailSalesData'!$A:$L,'Raw RetailSalesData'!A17)=1,'Raw RetailSalesData'!A17,"") -> ORD-10016 | B17: =IF('Raw RetailSalesData'!B17="","UNKNOWN",'Raw RetailSalesData'!B17) -> 2024-07-08 | C17: =IF('Raw RetailSalesData'!C17="","UNKNOW",'Raw RetailSalesData'!C17) -> UNKNOW | D17: =IF('Raw RetailSalesData'!D17="","UNKNOW",'Raw RetailSalesData'!D17) -> P203 | E17: =IF('Raw RetailSalesData'!E17="",'Raw RetailSalesData'!F17/'Raw RetailSalesData'!G17,'Raw RetailSalesData'!E17) -> 19 | F17: =IF('Raw RetailSalesData'!F17="",'Raw RetailSalesData'!G17/'Raw RetailSalesData'!E17,'Raw RetailSalesData'!F17) -> 63 | G17: =F17*E17 -> 1197 | H17: =IF('Raw RetailSalesData'!H17="","Unknown",'Raw RetailSalesData'!H17) -> LATAM | I17: Brazil | J17: SÃ£oPaulo | K17: =TRIM('Raw RetailSalesData'!K17) -> Sales Rep 5 | L17: Returning
A18: =IF(COUNTIF('Raw RetailSalesData'!$A:$L,'Raw RetailSalesData'!A18)=1,'Raw RetailSalesData'!A18,"") -> ORD-10017 | B18: =IF('Raw RetailSalesData'!B18="","UNKNOWN",'Raw RetailSalesData'!B18) -> 2024-09-30 | C18: =IF('Raw RetailSalesData'!C18="","UNKNOW",'Raw RetailSalesData'!C18) -> CUST-1166 | D18: =IF('Raw RetailSalesData'!D18="","UNKNOW",'Raw RetailSalesData'!D18) -> C303 | E18: =IF('Raw RetailSalesData'!E18="",'Raw RetailSalesData'!F18/'Raw RetailSalesData'!G18,'Raw RetailSalesData'!E18) -> 9 | F18: =IF('Raw RetailSalesData'!F18="",'Raw RetailSalesData'!G18/'Raw RetailSalesData'!E18,'Raw RetailSalesData'!F18) -> 55 | G18: =F18*E18 -> 495 | H18: =IF('Raw RetailSalesData'!H18="","Unknown",'Raw RetailSalesData'!H18) -> LATAM | I18: Brazil | J18: SÃ£oPaulo | K18: =TRIM('Raw RetailSalesData'!K18) -> Sales Rep 5 | L18: Returning
A19: =IF(COUNTIF('Raw RetailSalesData'!$A:$L,'Raw RetailSalesData'!A19)=1,'Raw RetailSalesData'!A19,"") -> ORD-10018 | B19: =IF('Raw RetailSalesData'!B19="","UNKNOWN",'Raw RetailSalesData'!B19) -> 2026-05-30 | C19: =IF('Raw RetailSalesData'!C19="","UNKNOW",'Raw RetailSalesData'!C19) -> CUST-1143 | D19: =IF('Raw RetailSalesData'!D19="","UNKNOW",'Raw RetailSalesData'!D19) -> C301 | E19: =IF('Raw RetailSalesData'!E19="",'Raw RetailSalesData'!F19/'Raw RetailSalesData'!G19,'Raw RetailSalesData'!E19) -> 18 | F19: =IF('Raw RetailSalesData'!F19="",'Raw RetailSalesData'!G19/'Raw RetailSalesData'!E19,'Raw RetailSalesData'!F19) -> 60 | G19: =F19*E19 -> 1080 | H19: =IF('Raw RetailSalesData'!H19="","Unknown",'Raw RetailSalesData'!H19) -> NA | I19: USA | J19: Chicago | K19: =TRIM('Raw RetailSalesData'!K19) -> Sales Rep 1 | L19: New
A20: =IF(COUNTIF('Raw RetailSalesData'!$A:$L,'Raw RetailSalesData'!A20)=1,'Raw RetailSalesData'!A20,"") -> ORD-10019 | B20: =IF('Raw RetailSalesData'!B20="","UNKNOWN",'Raw RetailSalesData'!B20) -> 2023-06-17 | C20: =IF('Raw RetailSalesData'!C20="","UNKNOW",'Raw RetailSalesData'!C20) -> CUST-1193 | D20: =IF('Raw RetailSalesData'!D20="","UNKNOW",'Raw RetailSalesData'!D20) -> P203 | E20: =IF('Raw RetailSalesData'!E20="",'Raw RetailSalesData'!F20/'Raw RetailSalesData'!G20,'Raw RetailSalesData'!E20) -> 14 | F20: =IF('Raw RetailSalesData'!F20="",'Raw RetailSalesData'!G20/'Raw RetailSalesData'!E20,'Raw RetailSalesData'!F20) -> 73 | G20: =F20*E20 -> 1022 | H20: =IF('Raw RetailSalesData'!H20="","Unknown",'Raw RetailSalesData'!H20) -> NA | I20: USA | J20: Chicago | K20: =TRIM('Raw RetailSalesData'!K20) -> Sales Rep 2 | L20: New
A21: =IF(COUNTIF('Raw RetailSalesData'!$A:$L,'Raw RetailSalesData'!A21)=1,'Raw RetailSalesData'!A21,"") -> ORD-10020 | B21: =IF('Raw RetailSalesData'!B21="","UNKNOWN",'Raw RetailSalesData'!B21) -> 2023-08-28 | C21: =IF('Raw RetailSalesData'!C21="","UNKNOW",'Raw RetailSalesData'!C21) -> CUST-1158 | D21: =IF('Raw RetailSalesData'!D21="","UNKNOW",'Raw RetailSalesData'!D21) -> C304 | E21: =IF('Raw RetailSalesData'!E21="",'Raw RetailSalesData'!F21/'Raw RetailSalesData'!G21,'Raw RetailSalesData'!E21) -> 18 | F21: =IF('Raw RetailSalesData'!F21="",'Raw RetailSalesData'!G21/'Raw RetailSalesData'!E21,'Raw RetailSalesData'!F21) -> 63 | G21: =F21*E21 -> 1134 | H21: =IF('Raw RetailSalesData'!H21="","Unknown",'Raw RetailSalesData'!H21) -> NA | I21: Canada | J21: Toronto | K21: =TRIM('Raw RetailSalesData'!K21) -> Sales Rep 5 | L21: VIP
... A910: =IF(COUNTIF('Raw RetailSalesData'!$A:$L,'Raw RetailSalesData'!A910)=1,'Raw RetailSalesData'!A910,"") -> ORD-10991 | B910: =IF('Raw RetailSalesData'!B910="","UNKNOWN",'Raw RetailSalesData'!B910) -> 2024-05-02 | C910: =IF('Raw RetailSalesData'!C910="","UNKNOW",'Raw RetailSalesData'!C910) -> CUST-1082 | D910: =IF('Raw RetailSalesData'!D910="","UNKNOW",'Raw RetailSalesData'!D910) -> P201 | E910: =IF('Raw RetailSalesData'!E910="",'Raw RetailSalesData'!F910/'Raw RetailSalesData'!G910,'Raw RetailSalesData'!E910) -> 3 | F910: =IF('Raw RetailSalesData'!F910="",'Raw RetailSalesData'!G910/'Raw RetailSalesData'!E910,'Raw RetailSalesData'!F910) -> 70 | G910: =F910*E910 -> 210 | H910: =IF('Raw RetailSalesData'!H910="","Unknown",'Raw RetailSalesData'!H910) -> EMEA | I910: France | J910: Paris | K910: =TRIM('Raw RetailSalesData'!K910) -> Sales Rep 3 | L910: VIP
A911: =IF(COUNTIF('Raw RetailSalesData'!$A:$L,'Raw RetailSalesData'!A912)=1,'Raw RetailSalesData'!A912,"") -> ORD-10993 | B911: =IF('Raw RetailSalesData'!B912="","UNKNOWN",'Raw RetailSalesData'!B912) -> 2025-04-26 | C911: =IF('Raw RetailSalesData'!C912="","UNKNOW",'Raw RetailSalesData'!C912) -> CUST-1083 | D911: =IF('Raw RetailSalesData'!D912="","UNKNOW",'Raw RetailSalesData'!D912) -> P201 | E911: =IF('Raw RetailSalesData'!E912="",'Raw RetailSalesData'!F912/'Raw RetailSalesData'!G912,'Raw RetailSalesData'!E912) -> 7 | F911: =IF('Raw RetailSalesData'!F912="",'Raw RetailSalesData'!G912/'Raw RetailSalesData'!E912,'Raw RetailSalesData'!F912) -> 65 | G911: =F911*E911 -> 455 | H911: =IF('Raw RetailSalesData'!H912="","Unknown",'Raw RetailSalesData'!H912) -> LATAM | I911: Argentina | J911: BuenosAires | K911: =TRIM('Raw RetailSalesData'!K911) -> John Smith | L911: Unknown
A912: =IF(COUNTIF('Raw RetailSalesData'!$A:$L,'Raw RetailSalesData'!A913)=1,'Raw RetailSalesData'!A913,"") -> ORD-10994 | B912: =IF('Raw RetailSalesData'!B913="","UNKNOWN",'Raw RetailSalesData'!B913) -> 2026-01-16 | C912: =IF('Raw RetailSalesData'!C913="","UNKNOW",'Raw RetailSalesData'!C913) -> CUST-1143 | D912: =IF('Raw RetailSalesData'!D913="","UNKNOW",'Raw RetailSalesData'!D913) -> UNKNOW | E912: =IF('Raw RetailSalesData'!E913="",'Raw RetailSalesData'!F913/'Raw RetailSalesData'!G913,'Raw RetailSalesData'!E913) -> 20 | F912: =IF('Raw RetailSalesData'!F913="",'Raw RetailSalesData'!G913/'Raw RetailSalesData'!E913,'Raw RetailSalesData'!F913) -> 53 | G912: =F912*E912 -> 1060 | H912: =IF('Raw RetailSalesData'!H913="","Unknown",'Raw RetailSalesData'!H913) -> LATAM | I912: Brazil | J912: SÃ£oPaulo | K912: =TRIM('Raw RetailSalesData'!K912) -> Sales Rep 4 | L912: Returning
A913: =IF(COUNTIF('Raw RetailSalesData'!$A:$L,'Raw RetailSalesData'!A914)=1,'Raw RetailSalesData'!A914,"") -> ORD-10995 | B913: =IF('Raw RetailSalesData'!B914="","UNKNOWN",'Raw RetailSalesData'!B914) -> 2026-01-16 | C913: =IF('Raw RetailSalesData'!C914="","UNKNOW",'Raw RetailSalesData'!C914) -> CUST-1143 | D913: =IF('Raw RetailSalesData'!D914="","UNKNOW",'Raw RetailSalesData'!D914) -> C304 | E913: =IF('Raw RetailSalesData'!E914="",'Raw RetailSalesData'!F914/'Raw RetailSalesData'!G914,'Raw RetailSalesData'!E914) -> 20 | F913: =IF('Raw RetailSalesData'!F914="",'Raw RetailSalesData'!G914/'Raw RetailSalesData'!E914,'Raw RetailSalesData'!F914) -> 53 | G913: =F913*E913 -> 1060 | H913: =IF('Raw RetailSalesData'!H914="","Unknown",'Raw RetailSalesData'!H914) -> LATAM | I913: Brazil | J913: SÃ£oPaulo | K913: =TRIM('Raw RetailSalesData'!K913) -> Sales Rep 4 | L913: Returning
A914: =IF(COUNTIF('Raw RetailSalesData'!$A:$L,'Raw RetailSalesData'!A915)=1,'Raw RetailSalesData'!A915,"") -> ORD-10996 | B914: =IF('Raw RetailSalesData'!B915="","UNKNOWN",'Raw RetailSalesData'!B915) -> 2025-08-08 | C914: =IF('Raw RetailSalesData'!C915="","UNKNOW",'Raw RetailSalesData'!C915) -> CUST-1077 | D914: =IF('Raw RetailSalesData'!D915="","UNKNOW",'Raw RetailSalesData'!D915) -> P101 | E914: =IF('Raw RetailSalesData'!E915="",'Raw RetailSalesData'!F915/'Raw RetailSalesData'!G915,'Raw RetailSalesData'!E915) -> 9 | F914: =IF('Raw RetailSalesData'!F915="",'Raw RetailSalesData'!G915/'Raw RetailSalesData'!E915,'Raw RetailSalesData'!F915) -> 90 | G914: =F914*E914 -> 810 | H914: =IF('Raw RetailSalesData'!H915="","Unknown",'Raw RetailSalesData'!H915) -> NA | I914: USA | J914: NewYork | K914: =TRIM('Raw RetailSalesData'!K914) -> Sales Rep 4 | L914: VIP
A915: =IF(COUNTIF('Raw RetailSalesData'!$A:$L,'Raw RetailSalesData'!A916)=1,'Raw RetailSalesData'!A916,"") -> ORD-10997 | B915: =IF('Raw RetailSalesData'!B916="","UNKNOWN",'Raw RetailSalesData'!B916) -> 2024-02-17 | C915: =IF('Raw RetailSalesData'!C916="","UNKNOW",'Raw RetailSalesData'!C916) -> CUST-1128 | D915: =IF('Raw RetailSalesData'!D916="","UNKNOW",'Raw RetailSalesData'!D916) -> C301 | E915: =IF('Raw RetailSalesData'!E916="",'Raw RetailSalesData'!F916/'Raw RetailSalesData'!G916,'Raw RetailSalesData'!E916) -> 9 | F915: =IF('Raw RetailSalesData'!F916="",'Raw RetailSalesData'!G916/'Raw RetailSalesData'!E916,'Raw RetailSalesData'!F916) -> 55 | G915: =F915*E915 -> 495 | H915: =IF('Raw RetailSalesData'!H916="","Unknown",'Raw RetailSalesData'!H916) -> EMEA | I915: Germany | J915: Berlin | K915: =TRIM('Raw RetailSalesData'!K915) -> Michael Johnson | L915: VIP
A916: =IF(COUNTIF('Raw RetailSalesData'!$A:$L,'Raw RetailSalesData'!A917)=1,'Raw RetailSalesData'!A917,"") -> ORD-10998 | B916: =IF('Raw RetailSalesData'!B917="","UNKNOWN",'Raw RetailSalesData'!B917) -> 2025-05-13 | C916: =IF('Raw RetailSalesData'!C917="","UNKNOW",'Raw RetailSalesData'!C917) -> CUST-1138 | D916: =IF('Raw RetailSalesData'!D917="","UNKNOW",'Raw RetailSalesData'!D917) -> P101 | E916: =IF('Raw RetailSalesData'!E917="",'Raw RetailSalesData'!F917/'Raw RetailSalesData'!G917,'Raw RetailSalesData'!E917) -> 12 | F916: =IF('Raw RetailSalesData'!F917="",'Raw RetailSalesData'!G917/'Raw RetailSalesData'!E917,'Raw RetailSalesData'!F917) -> 85 | G916: =F916*E916 -> 1020 | H916: =IF('Raw RetailSalesData'!H917="","Unknown",'Raw RetailSalesData'!H917) -> APAC | I916: Japan | J916: Tokyo | K916: =TRIM('Raw RetailSalesData'!K916) -> Sales Rep 5 | L916: VIP
A917: =IF(COUNTIF('Raw RetailSalesData'!$A:$L,'Raw RetailSalesData'!A918)=1,'Raw RetailSalesData'!A918,"") -> ORD-10999 | B917: =IF('Raw RetailSalesData'!B918="","UNKNOWN",'Raw RetailSalesData'!B918) -> 2026-03-23 | C917: =IF('Raw RetailSalesData'!C918="","UNKNOW",'Raw RetailSalesData'!C918) -> CUST-1040 | D917: =IF('Raw RetailSalesData'!D918="","UNKNOW",'Raw RetailSalesData'!D918) -> P101 | E917: =IF('Raw RetailSalesData'!E918="",'Raw RetailSalesData'!F918/'Raw RetailSalesData'!G918,'Raw RetailSalesData'!E918) -> 1 | F917: =IF('Raw RetailSalesData'!F918="",'Raw RetailSalesData'!G918/'Raw RetailSalesData'!E918,'Raw RetailSalesData'!F918) -> 90 | G917: =F917*E917 -> 90 | H917: =IF('Raw RetailSalesData'!H918="","Unknown",'Raw RetailSalesData'!H918) -> NA | I917: USA | J917: Chicago | K917: =TRIM('Raw RetailSalesData'!K917) -> Hiroshi Tanaka | L917: New
A918: =IF(COUNTIF('Raw RetailSalesData'!$A:$L,'Raw RetailSalesData'!A919)=1,'Raw RetailSalesData'!A919,"") -> ORD-11000 | B918: =IF('Raw RetailSalesData'!B919="","UNKNOWN",'Raw RetailSalesData'!B919) -> 2024-12-26 | C918: =IF('Raw RetailSalesData'!C919="","UNKNOW",'Raw RetailSalesData'!C919) -> CUST-1133 | D918: =IF('Raw RetailSalesData'!D919="","UNKNOW",'Raw RetailSalesData'!D919) -> P101 | E918: =IF('Raw RetailSalesData'!E919="",'Raw RetailSalesData'!F919/'Raw RetailSalesData'!G919,'Raw RetailSalesData'!E919) -> 20 | F918: =IF('Raw RetailSalesData'!F919="",'Raw RetailSalesData'!G919/'Raw RetailSalesData'!E919,'Raw RetailSalesData'!F919) -> 80 | G918: =F918*E918 -> 1600 | H918: =IF('Raw RetailSalesData'!H919="","Unknown",'Raw RetailSalesData'!H919) -> LATAM | I918: Argentina | J918: BuenosAires | K918: =TRIM('Raw RetailSalesData'!K918) -> Sales Rep 1 | L918: New

Sheet Piovt Table
A1: Sales Person | B1: Sum of Total Revenue | D1: Customer Type | E1: Sum of Total Revenue
A2: #N/A | B2: 7592.8 | D2: #N/A | E2: 3119
A3: Aarav Patel | B3: 34746.154 | D3: New | E3: 227438.41
A4: Hiroshi Tanaka | B4: 51322.958 | D4: Returning | E4: 201708.43
A5: John Smith | B5: 60178.25 | D5: Unknown | E5: 18097
A6: Michael Johnson | B6: 50346.437 | D6: VIP | E6: 214282.46
A7: Sales Rep 1 | B7: 84237.667 | D7: (blank)
A8: Sales Rep 2 | B8: 89326.95 | D8: Grand Total | E8: 664645.3
A9: Sales Rep 3 | B9: 79126.778
A10: Sales Rep 4 | B10: 94784.028
A11: Sales Rep 5 | B11: 94493.279
A12: Unknown | B12: 18490
A13: (blank)
A14: Grand Total | B14: 664645.3
A16: Region | B16: Count of Unite sold | D16: Customer Type | E16: Count of Unite sold | F16: Sum of Total Revenue
A17: APAC | B17: 12 | D17: #N/A | E17: 5 | F17: 3119
A18: EMEA | B18: 10 | D18: New | E18: 301 | F18: 227438.41
A19: LATAM | B19: 10 | D19: Returning | E19: 290 | F19: 201708.43
A20: NA | B20: 8 | D20: Unknown | E20: 30 | F20: 18097
A21: #N/A | B21: 5 | D21: VIP | E21: 291 | F21: 214282.46
A22: APAC | B22: 224 | D22: (blank)
A23: EMEA | B23: 186 | D23: Grand Total | E23: 917 | F23: 664645.3
A24: LATAM | B24: 216
A25: NA | B25: 214
A26: Unknown | B26: 32
A27: (blank)
A28: Grand Total | B28: 917
